Workbook

Sheet TOTALS
B4: Auction Type | C4: Ended | D4: No. Lots | E4: Lots Paid | F4: % Complete | G4: Total Hammer Price | H4: JZ Gross Proceeds | I4: CGC Auth Fee Total | J4: JZ Net Proceeds
B5: Weekly Auction | C5: 46074 | D5: ='2-21'!A62 -> 59 | E5: ='2-21'!H62 -> 58 | F5: =Table1[[#This Row],[Lots Paid]]/Table1[[#This Row],[No. Lots]] -> 0.98305085 | G5: ='2-21'!C62 -> 16993 | H5: =+'2-21'!E62 -> 18601.045 | I5: ='2-21'!F62 -> -84 | J5: ='2-21'!G62 -> 18517.035
B6: Weekly Auction | C6: 46082 | D6: =+'3-1'!A22 -> 19 | E6: =+'3-1'!H22 -> 19 | F6: =+Table1[[#This Row],[Lots Paid]]/Table1[[#This Row],[No. Lots]] -> 1 | G6: =+'3-1'!C22 -> 4025 | H6: =+'3-1'!E22 -> 4395.755 | I6: =+'3-1'!F22 -> -51 | J6: =+'3-1'!G22 -> 4344.755
B7: Weekly Auction | C7: 46103 | D7: =+'3-22'!A81 -> 78 | E7: =+'3-22'!H81 -> 78 | F7: =+Table1[[#This Row],[Lots Paid]]/Table1[[#This Row],[No. Lots]] -> 1 | G7: =+'3-22'!C81 -> 3326 | H7: =+'3-22'!E81 -> 3578.205 | I7: =+'3-22'!F81 -> -219 | J7: =+'3-22'!G81 -> 3359.205
B8: Weekly Auction | C8: 46110 | D8: =+'3-29'!A26 -> 23 | E8: =+'3-29'!H26 -> 23 | F8: =+Table1[[#This Row],[Lots Paid]]/Table1[[#This Row],[No. Lots]] -> 1 | G8: =+'3-29'!C26 -> 1768 | H8: =+'3-29'!E26 -> 1913.55 | I8: =+'3-29'!F26 -> -60 | J8: =+'3-29'!G26 -> 1853.55
B9: Weekly Auction | C9: 46117 | D9: =+'4-5'!A6 -> 3 | E9: =+'4-5'!H6 -> 3 | F9: =+Table1[[#This Row],[Lots Paid]]/Table1[[#This Row],[No. Lots]] -> 1 | G9: =+'4-5'!C6 -> 85 | H9: =+'4-5'!E6 -> 89.25 | I9: =+'4-5'!F6 -> -9 | J9: =+'4-5'!G6 -> 80.25
B10: Weekly Auction | C10: 46124 | D10: =+'4-12'!A14 -> 11 | E10: =+'4-12'!H14 -> 11 | F10: =+Table1[[#This Row],[Lots Paid]]/Table1[[#This Row],[No. Lots]] -> 1 | G10: =+'4-12'!C14 -> 496 | H10: =+'4-12'!E14 -> 536.8 | I10: =+'4-12'!F14 -> -33 | J10: =+'4-12'!G14 -> 503.8
B11: Weekly Auction | C11: 46131 | D11: =+'4-19'!A5 -> 2 | E11: =+'4-19'!H5 -> 2 | F11: =+Table1[[#This Row],[Lots Paid]]/Table1[[#This Row],[No. Lots]] -> 1 | G11: =+'4-19'!C5 -> 82 | H11: =+'4-19'!E5 -> 86.1 | I11: =+'4-19'!F5 -> -6 | J11: =+'4-19'!G5 -> 80.1
B12: Weekly Auction | C12: 46138 | D12: =+'4-26'!A25 -> 22 | E12: =+'4-26'!H25 -> 21 | F12: =+Table1[[#This Row],[Lots Paid]]/Table1[[#This Row],[No. Lots]] -> 0.95454545 | G12: =+'4-26'!C25 -> 786 | H12: =+'4-26'!E25 -> 836.275 | I12: =+'4-26'!F25 -> -66 | J12: =+'4-26'!G25 -> 773.275
B13: Weekly Auction | C13: 46145 | D13: =+'5-3'!A20 -> 17 | E13: =+'5-3'!H20 -> 17 | F13: =+Table1[[#This Row],[Lots Paid]]/Table1[[#This Row],[No. Lots]] -> 1 | G13: =+'5-3'!C20 -> 1461 | H13: =+'5-3'!E20 -> 1581.395 | I13: =+'5-3'!F20 -> -51 | J13: =+'5-3'!G20 -> 1530.395
B14: Weekly Auction | C14: 46152 | D14: =+'5-10'!A11 -> 8 | E14: =+'5-10'!H11 -> 8 | F14: =+Table1[[#This Row],[Lots Paid]]/Table1[[#This Row],[No. Lots]] -> 1 | G14: =+'5-10'!C11 -> 1834 | H14: ='5-10'!E11 -> 2010.35 | I14: =+'5-10'!F11 -> -18 | J14: =+'5-10'!G11 -> 1992.35
B15: TOTALS | C15: 3 Auctions | D15: =SUM(D5:D14) -> 242 | E15: =SUM(E5:E14) -> 240 | F15: =Table1[[#This Row],[Lots Paid]]/Table1[[#This Row],[No. Lots]] -> 0.99173554 | G15: =SUM(G5:G14) -> 30856 | H15: =+SUM(H5:H14) -> 33628.725 | I15: =SUM(I5:I14) -> -597 | J15: =SUM(J5:J14) -> 33034.715
H16: Less Previously Paid Out: | I16: 22861.79 | J16: =+J15-Table1[[#This Row],[CGC Auth Fee Total]] -> 10172.925
H17: Less Store Credit Used: | I17: 685.38 | J17: =+J16-Table1[[#This Row],[CGC Auth Fee Total]] -> 9487.545
H18: Less Outbound Shipping: | I18: 24.86 | J18: =+J17-Table1[[#This Row],[CGC Auth Fee Total]] -> 9462.685
I19: CONSIGNOR OWED: | J19: =+J18 -> 9462.685

Sheet 2-21
A1: Lot No. | B1: Title | C1: Hammer Price | D1: Split | E1: JZ Gross Proceeds | F1: CGC Auth. Fee | G1: JZ Net Proceeds | H1: Payout Status | I1: Sale Date | J1: Bids | L1: WH Net
A2: 2555 | B2: 2022 National Treasures Treasured Moments '25 Black Box Stephen Curry AUTO 1/1 #TM-SCY | C2: 2600 | D2: 1.1 | E2: 2860 | G2: 2860 | H2: Payment Complete | I2: 46074 | J2: 37 | K2: 2886 | L2: =+K2-E2 -> 26
A3: 2922 | B3: 2024 Panini Prizm Black Prizmatrix Gold Shimmer Luka Doncic AUTO 1/10 #PS-LUK | C3: 1800 | D3: 1.1 | E3: 1980 | G3: 1980 | H3: Payment Complete | I3: 46074 | J3: 22 | K3: 1998 | L3: =+K3-E3 -> 18
A4: 2522 | B4: 2021 Panini Flawless Draft Gem Luka Doncic AUTO /25 #DGS-LDD | C4: 1050 | D4: 1.1 | E4: 1155 | G4: 1155 | H4: Payment Complete | I4: 46074 | J4: 12 | K4: 1165.5 | L4: =+K4-E4 -> 10.5
A5: 2461 | B5: 2020 National Treasures Horizontal '25 Black Box Tyrese Maxey ROOKIE PATCH AUTO 1/1 #114 | C5: 1050 | D5: 1.1 | E5: 1155 | G5: 1155 | H5: Payment Complete | I5: 46074 | J5: 19 | K5: 1165.5 | L5: =+K5-E5 -> 10.5
A6: 2460 | B6: 2020 National Treasures Colossal White Box Tyrese Maxey ROOKIE PATCH AUTO 1/1 #CM-TMX | C6: 900 | D6: 1.1 | E6: 990 | G6: 990 | H6: Payment Complete | I6: 46074 | J6: 28 | K6: 999 | L6: =+K6-E6 -> 9
A7: 2510 | B7: 2021 Panini One And One Timeless Moments Purple Nikola Jokic AUTO /35 #TM-NJK | C7: 725 | D7: 1.1 | E7: 797.5 | G7: 797.5 | H7: Payment Complete | I7: 46074 | J7: 16 | K7: 804.75 | L7: =+K7-E7 -> 7.25
A8: 2810 | B8: 2024 Panini Silhouette NBA Cup FOTL Red Stephen Curry AUTO 1/7 #CUP-CUR | C8: 725 | D8: 1.1 | E8: 797.5 | G8: 797.5 | H8: Payment Complete | I8: 46074 | J8: 24 | K8: 804.75 | L8: =+K8-E8 -> 7.25
A9: 1198 | B9: 2024 Topps Transcendent Collection Showcase Blue Paul Skenes ROOKIE AUTO /10 #RSA-PS | C9: 700 | D9: 1.1 | E9: 770 | G9: 770 | H9: Payment Complete | I9: 46074 | J9: 18 | K9: 777 | L9: =+K9-E9 -> 7
A10: 2424 | B10: 2019 Panini One And One 1st Team '25 Black Box Nikola Jokic AUTO 1/1 #FT-NJK | C10: 675 | D10: 1.1 | E10: 742.5 | G10: 742.5 | H10: Payment Complete | I10: 46074 | J10: 16 | K10: 749.25 | L10: =+K10-E10 -> 6.75
A11: 2556 | B11: 2022 National Treasures Clutch Factor '25 Black Box Paolo Banchero ROOKIE PATCH AUTO 1/1 | C11: 550 | D11: 1.1 | E11: 605 | G11: 605 | H11: Payment Complete | I11: 46074 | J11: 11 | K11: 610.5 | L11: =+K11-E11 -> 5.5
A12: 1075 | B12: 2023 Topps Dynasty Silver Vladimir Guerrero Jr. PATCH AUTO /5 #DAPB-VGJ1 | C12: 460 | D12: 1.1 | E12: 506 | G12: 506 | H12: Payment Complete | I12: 46074 | J12: 15 | K12: 510.6 | L12: =+K12-E12 -> 4.6
A13: 2515 | B13: 2021 Panini Eminence Jumbo Gold Ja Morant PATCH AUTO 1/5 #JPA-JAM | C13: 400 | D13: 1.1 | E13: 440 | G13: 440 | H13: Payment Complete | I13: 46074 | J13: 32 | K13: 444 | L13: =+K13-E13 -> 4
A14: 2860 | B14: 2024 Panini Flawless All-NBA Diamond Gems Luka Doncic /10 #182 | C14: 360 | D14: 1.1 | E14: 396 | G14: 396 | H14: Payment Complete | I14: 46074 | J14: 19 | K14: 399.6 | L14: =+K14-E14 -> 3.6
A15: 2544 | B15: 2021 Select Black Snakeskin Pulsar Bones Hyland ROOKIE PATCH AUTO 1/1 #RJ-BHY CGC AUTH | C15: 310 | D15: 1.1 | E15: 341 | F15: -3 | G15: 338 | H15: Payment Complete | I15: 46074 | J15: 28 | K15: 344.1 | L15: =+K15-E15 -> 3.1
A16: 1548 | B16: 2025 Topps All Kings Vladimir Guerrero Jr. #AK-10 CGC AUTH | C16: 280 | D16: 1.1 | E16: 308 | F16: -3 | G16: 305 | H16: Payment Complete | I16: 46074 | J16: 16 | K16: 310.8 | L16: =+K16-E16 -> 2.8
A17: 2540 | B17: 2021 Immaculate Collection Massive Memorabilia Cade Cunningham ROOKIE PATCH 25/25 CGC AUTH | C17: 280 | D17: 1.1 | E17: 308 | F17: -3 | G17: 305 | H17: Payment Complete | I17: 46074 | J17: 11 | K17: 310.8 | L17: =+K17-E17 -> 2.8
A18: 2559 | B18: 2022 Panini One And One Purple Paolo Banchero ROOKIE PATCH AUTO 35/35 #RJA-PB5 | C18: 260 | D18: 1.1 | E18: 286 | G18: 286 | H18: Payment Complete | I18: 46074 | J18: 32 | K18: 288.6 | L18: =+K18-E18 -> 2.6
A19: 3112 | B19: 2024 Panini Origins Origin Stories Green Stephen Curry /5 #4 CGC AUTH | C19: 230 | D19: 1.1 | E19: 253 | F19: -3 | G19: 250 | H19: Payment Complete | I19: 46074 | J19: 19 | K19: 255.3 | L19: =+K19-E19 -> 2.3
A20: 2463 | B20: 2020 Panini Spectra Astral Prizm Tyrese Maxey ROOKIE PATCH AUTO 35/35 #204 | C20: 230 | D20: 1.1 | E20: 253 | G20: 253 | H20: Payment Complete | I20: 46074 | J20: 31 | K20: 255.3 | L20: =+K20-E20 -> 2.3
A21: 2509 | B21: 2021 Panini One And One Red Alperen Sengun ROOKIE PATCH AUTO 25/25 #RJ-ASG | C21: 210 | D21: 1.1 | E21: 231 | G21: 231 | H21: Payment Complete | I21: 46074 | J21: 38 | K21: 233.1 | L21: =+K21-E21 -> 2.1
A22: 2513 | B22: 2025 Panini The National VIP Wave Nikola Jokic AUTO /10 #20 CGC AUTH | C22: 190 | D22: 1.075 | E22: 204.25 | F22: -3 | G22: 201.25 | H22: Payment Complete | I22: 46074 | J22: 9 | K22: 209 | L22: =+K22-E22 -> 4.75
A23: 5136 | B23: 2025 Panini The National VIP Gold Giannis Antetokounmpo /10 #22 CGC AUTH | C23: 180 | D23: 1.075 | E23: 193.5 | F23: -3 | G23: 190.5 | H23: Payment Complete | I23: 46074 | J23: 7 | K23: 198 | L23: =+K23-E23 -> 4.5
A24: 1179 | B24: 2024 Panini Flawless Prime Sapphire Bobby Witt Jr. PATCH AUTO /15 #PPH-BWJ | C24: 175 | D24: 1.075 | E24: 188.125 | G24: 188.125 | H24: Payment Complete | I24: 46074 | J24: 25 | K24: 192.5 | L24: =+K24-E24 -> 4.375
A25: 3090 | B25: 2024 Panini Mosaic Elevate White Fluorescent Victor Wembanyama /10 #11 CGC AUTH | C25: 170 | D25: 1.075 | E25: 182.75 | F25: -3 | G25: 179.75 | H25: Payment Complete | I25: 46074 | J25: 38 | K25: 187 | L25: =+K25-E25 -> 4.25
A26: 2809 | B26: 2024 Panini The National VIP Diamond Gems Charles Barkley 1/1 #CB | C26: 165 | D26: 1.075 | E26: 177.375 | G26: 177.375 | H26: Payment Complete | I26: 46074 | J26: 14 | K26: 181.5 | L26: =+K26-E26 -> 4.125
A27: 2421 | B27: 2019 Crown Royale Silhouettes '22 Black Box Tyler Herro ROOKIE PATCH AUTO 1/1 #132 | C27: 160 | D27: 1.075 | E27: 172 | G27: 172 | H27: Payment Complete | I27: 46074 | J27: 15 | K27: 176 | L27: =+K27-E27 -> 4
A28: 3101 | B28: 2024 National Treasures Orange Ajay Mitchell ROOKIE PATCH AUTO /75 #148 CGC AUTH | C28: 160 | D28: 1.075 | E28: 172 | F28: -3 | G28: 169 | H28: Payment Complete | I28: 46074 | J28: 17 | K28: 176 | L28: =+K28-E28 -> 4
A29: 2794 | B29: 2024 Panini One And One Jumbo Red Jared McCain ROOKIE PATCH AUTO /25 #RJJ-JAR | C29: 150 | D29: 1.075 | E29: 161.25 | G29: 161.25 | H29: Payment Complete | I29: 46074 | J29: 40 | K29: 165 | L29: =+K29-E29 -> 3.75
A30: 3103 | B30: 2024 Panini Noir Color Holo Gold Jared McCain ROOKIE PATCH AUTO /25 #360 CGC AUTH | C30: 135 | D30: 1.075 | E30: 145.125 | F30: -3 | G30: 142.125 | H30: Payment Complete | I30: 46074 | J30: 48 | K30: 148.5 | L30: =+K30-E30 -> 3.375
A31: 3176 | B31: 2025 Topps '80-81 Silver Pack Gold Tracy McGrady AUTO /50 #80CA2-TMC CGC AUTH | C31: 125 | D31: 1.075 | E31: 134.38 | F31: -3 | G31: 131.38 | H31: Payment Complete | I31: 46074 | J31: 9 | K31: 137.5 | L31: =+K31-E31 -> 3.12
A32: 2263 | B32: 2012 Panini Signatures Red Yao Ming AUTO /10 #200 CGC AUTH | C32: 105 | D32: 1.075 | E32: 112.89 | F32: -3 | G32: 109.89 | H32: Payment Complete | I32: 46074 | J32: 25 | K32: 115.5 | L32: =+K32-E32 -> 2.61
A33: 3081 | B33: 2024 Immaculate Collection Immaculate Ink Gold John Stockton AUTO 10/10 #INK-JST CGC AUTH | C33: 100 | D33: 1.075 | E33: 107.5 | F33: -3 | G33: 104.5 | H33: Payment Complete | I33: 46074 | J33: 15 | K33: 110 | L33: =+K33-E33 -> 2.5
A34: 1332 | B34: 2025 Bowman Chrome Mega Box Purple Refractor Jesus Made PROSPECT AUTO /199 #BMA-JM | C34: 90 | D34: 1.075 | E34: 96.75 | G34: 96.75 | H34: Payment Complete | I34: 46074 | J34: 16 | K34: 97.2 | L34: =+K34-E34 -> 0.45
A35: 1992 | B35: 2025 Topps Tier One Jumbo Ronald Acuna Jr. PATCH AUTO /75 #AJR-RA CGC AUTH | C35: 88 | D35: 1.075 | E35: 94.6 | F35: -3 | G35: 91.6 | H35: Payment Complete | I35: 46074 | J35: 12 | K35: 95.04 | L35: =+K35-E35 -> 0.44
A36: 3080 | B36: 2024 Immaculate Collection Dual Bronny James Jr. LeBron James PATCH /99 #IDM-BJJ CGC AUTH | C36: 88 | D36: 1.075 | E36: 94.6 | F36: -3 | G36: 91.6 | H36: Payment Complete | I36: 46074 | J36: 13 | K36: 95.04 | L36: =+K36-E36 -> 0.44
A37: 5134 | B37: 2025 Panini The National VIP Hello Cracked Ice Caitlin Clark /45 #CC CGC AUTH | C37: 82 | D37: 1.075 | E37: 88.15 | F37: -3 | G37: 85.15 | H37: Payment Complete | I37: 46074 | J37: 9 | K37: 88.56 | L37: =+K37-E37 -> 0.41
A38: 2796 | B38: 2024 Panini One And One Of A Kind Green Damian Lillard AUTO /5 #OK-LIL | C38: 82 | D38: 1.075 | E38: 88.15 | G38: 88.15 | H38: Payment Complete | I38: 46074 | J38: 16 | K38: 88.56 | L38: =+K38-E38 -> 0.41
A39: 2513 | B39: 2021 Panini Instant Clear Vision Evan Mobley ROOKIE PATCH AUTO 10/10 #CV-3 | C39: 74 | D39: 1.075 | E39: 79.55 | G39: 79.55 | H39: Payment Complete | I39: 46074 | J39: 7 | K39: 79.92 | L39: =+K39-E39 -> 0.37
A40: 2542 | B40: 2021 National Treasures Evan Mobley ROOKIE PATCH AUTO /99 #RMD-EVM CGC AUTH | C40: 72 | D40: 1.075 | E40: 77.4 | F40: -3 | G40: 74.4 | H40: Payment Complete | I40: 46074 | J40: 6 | K40: 77.76 | L40: =+K40-E40 -> 0.36
...

Sheet 3-1
A1: Lot No. | B1: Title | C1: Hammer Price | D1: Split | E1: JZ Gross Proceeds | F1: CGC Auth. Fee | G1: JZ Net Proceeds | H1: Payout Status | I1: Sale Date | J1: Bids | L1: WH Net
A2: 6650 | B2: 2025 Panini The National VIP Wave Yao Ming AUTO 1/1 #19 CGC AUTH | C2: 725 | D2: 1.1 | E2: 797.5 | F2: -3 | G2: 794.5 | H2: Payment Complete | I2: 46082 | J2: 17 | K2: 804.75 | L2: =+K2-E2 -> 7.25
A3: 3455 | B3: 2023 Topps Three Rain Drops Platinum Tyrese Maxey AUTO 1/1 #RS-TM | C3: 675 | D3: 1.1 | E3: 742.5 | G3: 742.5 | H3: Payment Complete | I3: 46082 | J3: 23 | K3: 749.25 | L3: =+K3-E3 -> 6.75
A4: 3822 | B4: 2024 Bowman University Best Greatness Awaits Gold Geometric Kon Knueppel RC AUTO /50 CGC AUTH | C4: 320 | D4: 1.1 | E4: 352 | F4: -3 | G4: 349 | H4: Payment Complete | I4: 46082 | J4: 18 | K4: 355.2 | L4: =+K4-E4 -> 3.2
A5: 1791 | B5: 2025 Topps Holiday Red Glitter Ronald Acuna Jr. AUTO 1/10 #PA-RA CGC AUTH | C5: 250 | D5: 1.1 | E5: 275 | F5: -3 | G5: 272 | H5: Payment Complete | I5: 46082 | J5: 13 | K5: 277.5 | L5: =+K5-E5 -> 2.5
A6: 3824 | B6: 2024 Bowman University Best Possession Arrow Yellow Lazer Kon Knueppel AUTO /75 #PAAKK CGC AUTH | C6: 220 | D6: 1.1 | E6: 242 | F6: -3 | G6: 239 | H6: Payment Complete | I6: 46082 | J6: 21 | K6: 244.2 | L6: =+K6-E6 -> 2.2
A7: 6649 | B7: 2025 Panini The National VIP Blue Cracked Ice Caitlin Clark /75 #CC CGC AUTH | C7: 210 | D7: 1.1 | E7: 231 | F7: -3 | G7: 228 | H7: Payment Complete | I7: 46082 | J7: 26 | K7: 233.1 | L7: =+K7-E7 -> 2.1
A8: 3505 | B8: 2023 Panini Flawless Excellence Blue Donovan Mitchell AUTO /8 #ES-DMI CGC AUTH | C8: 200 | D8: 1.1 | E8: 220 | F8: -3 | G8: 217 | H8: Payment Complete | I8: 46082 | J8: 10 | K8: 222 | L8: =+K8-E8 -> 2
A9: 4244 | B9: 2025 Topps All Kings Egor Demin ROOKIE #AK-23 CGC AUTH | C9: 200 | D9: 1.1 | E9: 220 | F9: -3 | G9: 217 | H9: Payment Complete | I9: 46082 | J9: 21 | K9: 222 | L9: =+K9-E9 -> 2
A10: 2891 | B10: 2014 Panini Threads Prime Joel Embiid ROOKIE PATCH AUTO 25/25 #3 CGC AUTH | C10: 165 | D10: 1.075 | E10: 177.39 | F10: -3 | G10: 174.39 | H10: Payment Complete | I10: 46082 | J10: 7 | K10: 181.5 | L10: =+K10-E10 -> 4.11
A11: 3942 | B11: 2024 National Treasures Silver NBA Logos Kevin Durant RELIC /10 #49 CGC AUTH | C11: 160 | D11: 1.075 | E11: 172 | F11: -3 | G11: 169 | H11: Payment Complete | I11: 46082 | J11: 21 | K11: 176 | L11: =+K11-E11 -> 4
A12: 3935 | B12: 2024 National Treasures Quad Jared McCain ROOKIE PATCH AUTO /99 #RMQ-MCC CGC AUTH | C12: 150 | D12: 1.075 | E12: 161.25 | F12: -3 | G12: 158.25 | H12: Payment Complete | I12: 46082 | J12: 16 | K12: 165 | L12: =+K12-E12 -> 3.75
A13: 4074 | B13: 2024 Panini Prizm Deca Gold Shimmer FOTL Shaedon Sharpe AUTO /10 #PDS-SHA CGC AUTH | C13: 150 | D13: 1.075 | E13: 161.25 | F13: -3 | G13: 158.25 | H13: Payment Complete | I13: 46082 | J13: 10 | K13: 165 | L13: =+K13-E13 -> 3.75
A14: 4108 | B14: 2024 Select Score Select Throwback Tie-Dye Victor Wembanyama /25 #2 CGC AUTH | C14: 135 | D14: 1.075 | E14: 145.125 | F14: -3 | G14: 142.125 | H14: Payment Complete | I14: 46082 | J14: 11 | K14: 148.5 | L14: =+K14-E14 -> 3.375
A15: 3913 | B15: 2024 Immaculate Collection Chet Holmgren PATCH AUTO /15 #IRP-HOL CGC AUTH | C15: 125 | D15: 1.075 | E15: 134.39 | F15: -3 | G15: 131.39 | H15: Payment Complete | I15: 46082 | J15: 7 | K15: 137.5 | L15: =+K15-E15 -> 3.11
... A18: 6651 | B18: 2025 Panini The National VIP Memorabilia Gold Larry Bird PATCH /10 #15 CGC AUTH | C18: 76 | D18: 1.075 | E18: 81.7 | F18: -3 | G18: 78.7 | H18: Payment Complete | I18: 46082 | J18: 19 | K18: 82.08 | L18: =+K18-E18 -> 0.38
A19: 3555 | B19: 2024 Panini One And One Jared McCain ROOKIE AUTO /99 #RA-JAR | C19: 52 | D19: 1.075 | E19: 55.9 | G19: 55.9 | H19: Payment Complete | I19: 46082 | J19: 7 | K19: 56.16 | L19: =+K19-E19 -> 0.26
A20: 4551 | B20: 2025 Topps Chrome Chromographs Orange Refractor Jalen Williams AUTO /25 #CH-JW CGC AUTH | C20: 46 | D20: 1.05 | E20: 48.3 | F20: -3 | G20: 45.3 | H20: Payment Complete | I20: 46082 | J20: 10 | K20: 46.92 | L20: =+K20-E20 -> -1.38
A22: =COUNTA(A2:A20) -> 19 | B22: TOTALS | C22: =SUM(C2:C20) -> 4025 | E22: =+SUM(E2:E21) -> 4395.755 | F22: =SUM(F2:F20) -> -51 | G22: =+SUM(G2:G20) -> 4344.755 | H22: =COUNTA(H2:H20) -> 19 | L22: =SUM(L2:L20) -> 50.185

Sheet 3-22
A1: Lot No. | B1: Title | C1: Hammer Price | D1: Split | E1: JZ Gross Proceeds | F1: CGC Auth. Fee | G1: JZ Net Proceeds | H1: Payout Status | I1: Sale Date | J1: Bids | L1: WH Net
A2: 1209 | B2: 2024 Bowman Chrome Draft Black Refractor Sam Antonacci PROSPECT AUTO 1/10 #CPA-SA CGC AUTH | C2: 800 | D2: 1.1 | E2: 880 | F2: -3 | G2: 877 | H2: Payout Complete | I2: 46103 | J2: 17 | K2: 888 | L2: =+K2-E2 -> 8
A3: 4461 | B3: 2025 Topps Chrome Patented Stephen Curry #PD-2 CGC AUTH | C3: 210 | D3: 1.1 | E3: 231 | F3: -3 | G3: 228 | H3: Payout Complete | I3: 46103 | J3: 16 | K3: 233.1 | L3: =+K3-E3 -> 2.1
A4: 2627 | B4: 2002 Topps Xpectations Yao Ming AUTO #XA-YM CGC AUTH | C4: 195 | D4: 1.075 | E4: 209.63 | F4: -3 | G4: 206.63 | H4: Payout Complete | I4: 46103 | J4: 16 | K4: 214.5 | L4: =+K4-E4 -> 4.87
A5: 6552 | B5: 2018 Panini The National VIP Prizm Cristiano Ronaldo /99 #94 PSA 10 GEM MINT | C5: 165 | D5: 1.075 | E5: 177.375 | G5: 177.375 | H5: Payout Complete | I5: 46103 | J5: 10 | K5: 181.5 | L5: =+K5-E5 -> 4.125
A6: 4209 | B6: 2025 Topps Chrome '80-81 Silver Pack Orange Will Riley ROOKIE AUTO /25 #80CR2-WR CGC AUTH | C6: 96 | D6: 1.075 | E6: 103.2 | F6: -3 | G6: 100.2 | H6: Payout Complete | I6: 46103 | J6: 14 | K6: 103.68 | L6: =+K6-E6 -> 0.48
A7: 2759 | B7: 2010 Crown Royale National Convention VIP Kobe Bryant #VIP1 CGC AUTH | C7: 84 | D7: 1.075 | E7: 90.3 | F7: -3 | G7: 87.3 | H7: Payout Complete | I7: 46103 | J7: 15 | K7: 90.72 | L7: =+K7-E7 -> 0.42
A8: 4319 | B8: 2025 Topps Chrome Red White & Blue Refractor Kon Knueppel ROOKIE #254 CGC AUTH | C8: 84 | D8: 1.075 | E8: 90.3 | F8: -3 | G8: 87.3 | H8: Payout Complete | I8: 46103 | J8: 21 | K8: 90.72 | L8: =+K8-E8 -> 0.42
A9: 179 | B9: 1969 Topps Reggie Jackson ROOKIE #260 CGC AUTH | C9: 84 | D9: 1.075 | E9: 90.3 | F9: -3 | G9: 87.3 | H9: Payout Complete | I9: 46103 | J9: 22 | K9: 90.72 | L9: =+K9-E9 -> 0.42
A10: 1598 | B10: 2025 Leaf Baseball Nation MILB Top 100 Pink Sparkle Trey Yesavage ROOKIE AUTO 1/1 CGC AUTH | C10: 82 | D10: 1.075 | E10: 88.15 | F10: -3 | G10: 85.15 | H10: Payout Complete | I10: 46103 | J10: 18 | K10: 88.56 | L10: =+K10-E10 -> 0.41
A11: 3328 | B11: 2020 Immaculate Collection Remarkable Dual Anthony Edwards James Wiseman RC PATCH /75 CGC AUTH | C11: 72 | D11: 1.075 | E11: 77.4 | F11: -3 | G11: 74.4 | H11: Payout Complete | I11: 46103 | J11: 19 | K11: 77.76 | L11: =+K11-E11 -> 0.36
A12: 1949 | B12: 2022 Immaculate Collection Scorers Club Hakeem Olajuwon AUTO /49 #SCS-HOW CGC AUTH | C12: 70 | D12: 1.075 | E12: 75.25 | F12: -3 | G12: 72.25 | H12: Payout Complete | I12: 46103 | J12: 21 | K12: 75.6 | L12: =+K12-E12 -> 0.35
A13: 4463 | B13: 2025 Topps Chrome Rock Stars Die-Cut Ace Bailey ROOKIE #RS-20 CGC AUTH | C13: 68 | D13: 1.075 | E13: 73.1 | F13: -3 | G13: 70.1 | H13: Payout Complete | I13: 46103 | J13: 14 | K13: 73.44 | L13: =+K13-E13 -> 0.34
A14: 3977 | B14: 2024 Panini Photogenic Dual Gold Yuki Kawamura & Yongxi Cui ROOKIE AUTO JERSEY # 8/10 CGC AUTH | C14: 68 | D14: 1.075 | E14: 73.1 | F14: -3 | G14: 70.1 | H14: Payout Complete | I14: 46103 | J14: 21 | K14: 73.44 | L14: =+K14-E14 -> 0.34
A15: 4474 | B15: 2025 Topps Chrome Blue Refractor Will Riley ROOKIE AUTO /150 #TCAR-WR CGC AUTH | C15: 62 | D15: 1.075 | E15: 66.65 | F15: -3 | G15: 63.65 | H15: Payout Complete | I15: 46103 | J15: 13 | K15: 66.96 | L15: =+K15-E15 -> 0.31
A16: 3529 | B16: 2023 Panini Court Kings Water Color Sapphire Anthony Edwards JERSEY # 5/25 #6 PSA 9 MINT | C16: 62 | D16: 1.075 | E16: 66.65 | G16: 66.65 | H16: Payout Complete | I16: 46103 | J16: 11 | K16: 66.96 | L16: =+K16-E16 -> 0.31
A17: 4113 | B17: 2025 Leaf Metal Independence Day Patriotic Marine Corps War Memorial Cameron Boozer RC AUTO 1/1 | C17: 62 | D17: 1.075 | E17: 66.65 | G17: 66.65 | H17: Payout Complete | I17: 46103 | J17: 15 | K17: 66.96 | L17: =+K17-E17 -> 0.31
A18: 3977 | B18: 2024 Panini Photogenic Diamond Matas Buzelis ROOKIE AUTO 1/75 #RA-BUZ CGC AUTH | C18: 58 | D18: 1.075 | E18: 62.35 | F18: -3 | G18: 59.35 | H18: Payout Complete | I18: 46103 | J18: 16 | K18: 62.64 | L18: =+K18-E18 -> 0.29
A19: 3643 | B19: 2023 National Treasures Pink Anthony Edwards 15/15 #93 CGC AUTH | C19: 52 | D19: 1.075 | E19: 55.9 | F19: -3 | G19: 52.9 | H19: Payout Complete | I19: 46103 | J19: 12 | K19: 56.16 | L19: =+K19-E19 -> 0.26
A20: 4470 | B20: 2025 Topps Chrome Orange Geometric Refractor Walter Clayton Jr. ROOKIE AUTO /25 CGC AUTH | C20: 52 | D20: 1.075 | E20: 55.9 | F20: -3 | G20: 52.9 | H20: Payout Complete | I20: 46103 | J20: 10 | K20: 56.16 | L20: =+K20-E20 -> 0.26
A21: 3972 | B21: 2024 Panini Obsidian Volcanix Luka Doncic #20 CGC AUTH | C21: 39 | D21: 1.05 | E21: 40.95 | F21: -3 | G21: 37.95 | H21: Payout Complete | I21: 46103 | J21: 5 | K21: 39.78 | L21: =+K21-E21 -> -1.17
A22: 6105 | B22: 2024 Topps Chrome UFC Purple Shara Magomedov ROOKIE AUTO DNA 9 #141 PSA 9 MINT | C22: 36 | D22: 1.05 | E22: 37.8 | G22: 37.8 | H22: Payout Complete | I22: 46103 | J22: 7 | K22: 36.72 | L22: =+K22-E22 -> -1.08
A23: 5008 | B23: 2021 Absolute Jumbo Cleats Kenneth Gainwell ROOKIE PATCH /5 #JUM-KGA CGC AUTH | C23: 36 | D23: 1.05 | E23: 37.8 | F23: -3 | G23: 34.8 | H23: Payout Complete | I23: 46103 | J23: 9 | K23: 36.72 | L23: =+K23-E23 -> -1.08
A24: 3927 | B24: 2024 Panini Flawless Legendary Scripts Gold Metta World Peace AUTO #LSC-MWP CGC AUTH | C24: 34 | D24: 1.05 | E24: 35.7 | F24: -3 | G24: 32.7 | H24: Payout Complete | I24: 46103 | J24: 15 | K24: 34.68 | L24: =+K24-E24 -> -1.02
A25: 6746 | B25: 2024 Immaculate Collection Sophisticated Ruby Carlos Vela AUTO JERSEY # 11/30 #SS-CVE CGC AUTH | C25: 31 | D25: 1.05 | E25: 32.55 | F25: -3 | G25: 29.55 | H25: Payout Complete | I25: 46103 | J25: 20 | K25: 31.62 | L25: =+K25-E25 -> -0.93
A26: 6103 | B26: 2024 Topps Chrome UFC Blue Shara Magomedov ROOKIE AUTO DNA 10 /150 #141 PSA 9 MINT | C26: 31 | D26: 1.05 | E26: 32.55 | G26: 32.55 | H26: Payout Complete | I26: 46103 | J26: 7 | K26: 31.62 | L26: =+K26-E26 -> -0.93
A27: 5007 | B27: 2021 Leaf Metal Draft Portrait Gold Crystal DeVonta Smith ROOKIE AUTO 1/1 #PA-DS2 CGC AUTH | C27: 31 | D27: 1.05 | E27: 32.55 | F27: -3 | G27: 29.55 | H27: Payout Complete | I27: 46103 | J27: 10 | K27: 31.62 | L27: =+K27-E27 -> -0.93
A28: 1213 | B28: 2024 Bowman Chrome Draft Orange Wave Refractor Kavares Tears PROSPECT AUTO /25 #CPA-KT CGC AUTH | C28: 29 | D28: 1.05 | E28: 30.45 | F28: -3 | G28: 27.45 | H28: Payout Complete | I28: 46103 | J28: 15 | K28: 29.58 | L28: =+K28-E28 -> -0.87
A29: 4524 | B29: 2025 Topps Chrome Sky Write Orange Geometric Refractor Ajay Mitchell AUTO /25 #SWS-AM CGC AUTH | C29: 26 | D29: 1.05 | E29: 27.3 | F29: -3 | G29: 24.3 | H29: Payout Complete | I29: 46103 | J29: 8 | K29: 26.52 | L29: =+K29-E29 -> -0.78
A30: 3972 | B30: 2024 Panini Obsidian Trailblazer Electric Etch Molten Mojo OG Anunoby AUTO /10 #TA-OGA CGC AUTH | C30: 26 | D30: 1.05 | E30: 27.3 | F30: -3 | G30: 24.3 | H30: Payout Complete | I30: 46103 | J30: 9 | K30: 26.52 | L30: =+K30-E30 -> -0.78
A31: 1614 | B31: 2025 Panini Impeccable Elegance Holo Gold Kyle Teel ROOKIE PATCH AUTO JERSEY # 8/10 CGC AUTH | C31: 22 | D31: 1.05 | E31: 23.1 | F31: -3 | G31: 20.1 | H31: Payout Complete | I31: 46103 | J31: 15 | K31: 22.44 | L31: =+K31-E31 -> -0.66
A32: 4313 | B32: 2025 Topps Chrome Xfractor VJ Edgecombe ROOKIE #253 CGC AUTH | C32: 22 | D32: 1.05 | E32: 23.1 | F32: -3 | G32: 20.1 | H32: Payout Complete | I32: 46103 | J32: 8 | K32: 22.44 | L32: =+K32-E32 -> -0.66
A33: 3929 | B33: 2024 Immaculate Collection FOTL Devin Booker /11 #85 CGC AUTH | C33: 21 | D33: 1.05 | E33: 22.05 | F33: -3 | G33: 19.05 | H33: Payout Complete | I33: 46103 | J33: 8 | K33: 21.42 | L33: =+K33-E33 -> -0.63
A34: 3930 | B34: 2024 Immaculate Collection Modern Marks Ausar Thompson AUTO /99 #MM-AST CGC AUTH | C34: 21 | D34: 1.05 | E34: 22.05 | F34: -3 | G34: 19.05 | H34: Payout Complete | I34: 46103 | J34: 8 | K34: 21.42 | L34: =+K34-E34 -> -0.63
A35: 1909 | B35: 2025 Finest Gold Refractor Angel Martinez ROOKIE RELIC AUTO /50 #RAJR-AM CGC AUTH | C35: 20 | D35: 1.05 | E35: 21 | F35: -3 | G35: 18 | H35: Payout Complete | I35: 46103 | J35: 9 | K35: 20.4 | L35: =+K35-E35 -> -0.6
A36: 4086 | B36: 2024 Topps Chrome Red Geometric Refractor Dwyane Wade 5/5 #13 CGC AUTH | C36: 20 | D36: 1.05 | E36: 21 | F36: -3 | G36: 18 | H36: Payout Complete | I36: 46103 | J36: 6 | K36: 20.4 | L36: =+K36-E36 -> -0.6
A37: 1236 | B37: 2024 Panini Flawless Emerald Dalton Rushing ROOKIE PATCH AUTO /5 #PPA-DR CGC AUTH | C37: 20 | D37: 1.05 | E37: 21 | F37: -3 | G37: 18 | H37: Payout Complete | I37: 46103 | J37: 11 | K37: 20.4 | L37: =+K37-E37 -> -0.6
A38: 3902 | B38: 2024 Donruss Optic Blue Glitter Yao Ming JERSEY # 11/15 #226 CGC AUTH | C38: 19 | D38: 1.05 | E38: 19.95 | F38: -3 | G38: 16.95 | H38: Payout Complete | I38: 46103 | J38: 9 | K38: 19.38 | L38: =+K38-E38 -> -0.57
... A79: 3890 | B79: 2024 Bowman Chrome University Black & Gold Stealth Refractor Dame Sarr ROOKIE /24 #17 CGC AUTH | C79: 5 | D79: 1.05 | E79: 5.25 | F79: -3 | G79: 2.25 | H79: Payout Complete | I79: 46103 | J79: 1 | K79: 3 | L79: =+K79-E79 -> -2.25
A81: =COUNTA(A2:A79) -> 78 | B81: TOTALS | C81: =SUM(C2:C79) -> 3326 | E81: =+SUM(E2:E80) -> 3578.205 | F81: =SUM(F2:F79) -> -219 | G81: =+SUM(G2:G79) -> 3359.205 | H81: =COUNTA(H2:H79) -> 78 | L81: =SUM(L2:L79) -> -51.705

Sheet 3-29
A1: Lot No. | B1: Title | C1: Hammer Price | D1: Split | E1: JZ Gross Proceeds | F1: CGC Auth. Fee | G1: JZ Net Proceeds | H1: Payout Status | I1: Sale Date | J1: Bids | L1: WH Net
A2: 4737 | B2: 2024 Panini Flawless Mastercraft Jayson Tatum PATCH /5 #MC-JYT CGC AUTH | C2: 750 | D2: 1.1 | E2: 825 | F2: -3 | G2: 822 | H2: Payout Complete | I2: 46110 | J2: 13 | K2: 832.5 | L2: =+K2-E2 -> 7.5
A3: 4988 | B3: 2025 Topps Chrome Red White & Blue Refractor Cooper Flagg ROOKIE #251 CGC AUTH | C3: 140 | D3: 1.075 | E3: 150.5 | F3: -3 | G3: 147.5 | H3: Payout Complete | I3: 46110 | J3: 17 | K3: 154 | L3: =+K3-E3 -> 3.5
A4: 5043 | B4: 2025 Topps Chrome Glass Canvas Jalen Brunson #GC-17 CGC AUTH | C4: 110 | D4: 1.075 | E4: 118.25 | F4: -3 | G4: 115.25 | H4: Payout Complete | I4: 46110 | J4: 13 | K4: 121 | L4: =+K4-E4 -> 2.75
A5: 4997 | B5: 2025 Topps Chrome Red White & Blue Refractor Kon Knueppel ROOKIE #254 CGC AUTH | C5: 94 | D5: 1.075 | E5: 101.05 | F5: -3 | G5: 98.05 | H5: Payout Complete | I5: 46110 | J5: 13 | K5: 101.52 | L5: =+K5-E5 -> 0.47
A6: 4847 | B6: 2025 Leaf Signature Series Aquatic Clownfish Lava Cameron Boozer ROOKIE AUTO 1/1 #ACB3 CGC AUTH | C6: 90 | D6: 1.075 | E6: 96.75 | F6: -3 | G6: 93.75 | H6: Payout Complete | I6: 46110 | J6: 22 | K6: 97.2 | L6: =+K6-E6 -> 0.45
A7: 6598 | B7: 2024 Topps Chrome UFC Sepia Refractor Shara Magomedov ROOKIE AUTO DNA 10 #141 PSA 10 GEM MINT | C7: 70 | D7: 1.075 | E7: 75.25 | G7: 72.25 | H7: Payout Complete | I7: 46110 | J7: 25 | K7: 75.6 | L7: =+K7-E7 -> 0.35
A8: 5020 | B8: 2025 Topps Chrome Issue Ace Bailey ROOKIE AUTO #TAIR-AB CGC AUTH | C8: 66 | D8: 1.075 | E8: 70.95 | F8: -3 | G8: 67.95 | H8: Payout Complete | I8: 46110 | J8: 10 | K8: 71.28 | L8: =+K8-E8 -> 0.33
A9: 4762 | B9: 2024 Panini Obsidian Cutting Edge Electric Etch Orange Flood Stephen Curry PATCH /99 CGC AUTH | C9: 60 | D9: 1.075 | E9: 64.5 | F9: -3 | G9: 61.5 | H9: Payout Complete | I9: 46110 | J9: 17 | K9: 64.8 | L9: =+K9-E9 -> 0.3
A10: 4931 | B10: 2025 Topps Blackout Flash Drop LeBron James /50 #150 CGC AUTH | C10: 54 | D10: 1.075 | E10: 58.05 | F10: -3 | G10: 55.05 | H10: Payout Complete | I10: 46110 | J10: 9 | K10: 58.32 | L10: =+K10-E10 -> 0.27
A11: 5104 | B11: 2025 Topps Chrome Tall Tales Green Geometric Refractor LeBron James /99 #TT-7 CGC AUTH | C11: 52 | D11: 1.075 | E11: 55.9 | F11: -3 | G11: 52.9 | H11: Payout Complete | I11: 46110 | J11: 6 | K11: 56.16 | L11: =+K11-E11 -> 0.26
A12: 5063 | B12: 2025 Topps Chrome Geometric Refractor Will Riley ROOKIE AUTO #TCAR-WR CGC AUTH | C12: 50 | D12: 1.075 | E12: 53.75 | F12: -3 | G12: 50.75 | H12: Payout Complete | I12: 46110 | J12: 7 | K12: 54 | L12: =+K12-E12 -> 0.25
A13: 3934 | B13: 2017 Donruss Optic Stephen Curry #46 PSA 10 GEM MINT | C13: 45 | D13: 1.05 | E13: 47.25 | G13: 44.25 | H13: Payout Complete | I13: 46110 | J13: 12 | K13: 45.9 | L13: =+K13-E13 -> -1.35
A14: 4992 | B14: 2025 Topps Chrome Xfractor VJ Edgecombe ROOKIE #253 CGC AUTH | C14: 27 | D14: 1.05 | E14: 28.35 | F14: -3 | G14: 25.35 | H14: Payout Complete | I14: 46110 | J14: 8 | K14: 27.54 | L14: =+K14-E14 -> -0.81
A15: 6600 | B15: 2024 Topps Chrome UFC Refractor Shara Magomedov ROOKIE AUTO #141 PSA 9 MINT | C15: 24 | D15: 1.05 | E15: 25.2 | G15: 22.2 | H15: Payout Complete | I15: 46110 | J15: 13 | K15: 24.48 | L15: =+K15-E15 -> -0.72
A16: 2098 | B16: 2025 Panini The National VIP Hello Cracked Ice Aaron Judge /45 #43 CGC AUTH | C16: 21 | D16: 1.05 | E16: 22.05 | F16: -3 | G16: 19.05 | H16: Payout Complete | I16: 46110 | J16: 5 | K16: 21.42 | L16: =+K16-E16 -> -0.63
A17: 2097 | B17: 2025 Panini The National VIP Hello Cracked Ice Aaron Judge /45 #43 CGC AUTH | C17: 21 | D17: 1.05 | E17: 22.05 | F17: -3 | G17: 19.05 | H17: Payout Complete | I17: 46110 | J17: 5 | K17: 21.42 | L17: =+K17-E17 -> -0.63
A18: 2096 | B18: 2025 Panini The National VIP Blue Cracked Ice Aaron Judge /75 #43 CGC AUTH | C18: 18 | D18: 1.05 | E18: 18.9 | F18: -3 | G18: 18.9 | H18: Payout Complete | I18: 46110 | J18: 6 | K18: 18.36 | L18: =+K18-E18 -> -0.54
A19: 4555 | B19: 2024 Panini Prizm Draft Picks Rated Prospect Blue Seismic VJ Edgecombe ROOKIE /149 #17 CGC AUTH | C19: 14 | D19: 1.05 | E19: 14.7 | F19: -3 | G19: 14.7 | H19: Payout Complete | I19: 46110 | J19: 8 | K19: 13.8 | L19: =+K19-E19 -> -0.9
A20: 4554 | B20: 2024 Panini Prizm Draft Picks Rated Prospect Blue VJ Edgecombe ROOKIE /199 #17 CGC AUTH | C20: 13 | D20: 1.05 | E20: 13.65 | F20: -3 | G20: 13.65 | H20: Payout Complete | I20: 46110 | J20: 7 | K20: 12.6 | L20: =+K20-E20 -> -1.05
A21: 5110 | B21: 2025 Topps Chrome X's & Whoa's Cooper Flagg ROOKIE #XW-8 CGC AUTH | C21: 13 | D21: 1.05 | E21: 13.65 | F21: -3 | G21: 10.65 | H21: Payout Complete | I21: 46110 | J21: 3 | K21: 12.6 | L21: =+K21-E21 -> -1.05
A22: 4792 | B22: 2024 Panini Prizm Black Blue Shimmer FOTL Yao Ming /35 #264 CGC AUTH | C22: 13 | D22: 1.05 | E22: 13.65 | F22: -3 | G22: 10.65 | H22: Payout Complete | I22: 46110 | J22: 5 | K22: 12.6 | L22: =+K22-E22 -> -1.05
A23: 4999 | B23: 2025 Topps Chrome Xfractor Ace Bailey ROOKIE #255 CGC AUTH | C23: 12 | D23: 1.05 | E23: 12.6 | F23: -3 | G23: 9.6 | H23: Payout Complete | I23: 46110 | J23: 4 | K23: 11.4 | L23: =+K23-E23 -> -1.2
A24: 4556 | B24: 2024 Panini Prizm Draft Picks Rated Blue Wave VJ Edgecombe ROOKIE /249 #17 CGC AUTH | C24: 11 | D24: 1.05 | E24: 11.55 | F24: -3 | G24: 8.55 | H24: Payout Complete | I24: 46110 | J24: 7 | K24: 10.2 | L24: =+K24-E24 -> -1.35
A26: =COUNTA(A2:A24) -> 23 | B26: TOTALS | C26: =SUM(C2:C24) -> 1768 | E26: =+SUM(E2:E25) -> 1913.55 | F26: =SUM(F2:F24) -> -60 | G26: =+SUM(G2:G24) -> 1853.55 | H26: =COUNTA(H2:H24) -> 23 | L26: =SUM(L2:L24) -> 5.15

Sheet 4-5
A1: Lot No. | B1: Title | C1: Hammer Price | D1: Split | E1: JZ Gross Proceeds | F1: CGC Auth. Fee | G1: JZ Net Proceeds | H1: Payout Status | I1: Sale Date | J1: Bids | L1: WH Net
A2: 4911 | B2: 2025 Topps Chrome Xfractor VJ Edgecombe ROOKIE #253 CGC AUTH | C2: 37 | D2: 1.05 | E2: 38.85 | F2: -3 | G2: 35.85 | H2: Payout Complete | I2: 46117 | J2: 11 | K2: 37.74 | L2: =+K2-E2 -> -1.11
A3: 4912 | B3: 2025 Topps Chrome Xfractor VJ Edgecombe ROOKIE #253 CGC AUTH | C3: 40 | D3: 1.05 | E3: 42 | F3: -3 | G3: 39 | H3: Payout Complete | I3: 46117 | J3: 12 | K3: 40.8 | L3: =+K3-E3 -> -1.2
A4: 4786 | B4: 2025 Topps Rainbow Foil VJ Edgecombe ROOKIE #203 CGC AUTH | C4: 8 | D4: 1.05 | E4: 8.4 | F4: -3 | G4: 5.4 | H4: Payout Complete | I4: 46117 | J4: 3 | K4: 6.6 | L4: =+K4-E4 -> -1.8
A6: =COUNTA(A2:A4) -> 3 | B6: TOTALS | C6: =SUM(C2:C4) -> 85 | E6: =+SUM(E2:E5) -> 89.25 | F6: =SUM(F2:F4) -> -9 | G6: =+SUM(G2:G4) -> 80.25 | H6: =COUNTA(H2:H4) -> 3 | L6: =SUM(L2:L4) -> -4.11

Sheet 4-12
A1: Lot No. | B1: Title | C1: Hammer Price | D1: Split | E1: JZ Gross Proceeds | F1: CGC Auth. Fee | G1: JZ Net Proceeds | H1: Payout Status | I1: Sale Date | J1: Bids | L1: WH Net
A2: 1908 | B2: 2025 Bowman Chrome Yellow Refractor Charlie Condon PROSPECT AUTO /75 #CPA-CC CGC AUTH | C2: 320 | D2: 1.1 | E2: 352 | F2: -3 | G2: 349 | H2: Payout Complete | I2: 46124 | J2: 22 | K2: 355.2 | L2: =+K2-E2 -> 3.2
A3: 2208 | B3: 2025 Topps Heritage Chrome Gold Border Refractor Elly De La Cruz 1/50 #263 CGC AUTH | C3: 45 | D3: 1.05 | E3: 47.25 | F3: -3 | G3: 44.25 | H3: Payout Complete | I3: 46124 | J3: 10 | K3: 45.9 | L3: =+K3-E3 -> -1.35
A4: 2106 | B4: 2025 Topps Chrome Update All-Star Game Gold Refractor Elly De La Cruz /50 #ASGC-32 CGC AUTH | C4: 41 | D4: 1.05 | E4: 43.05 | F4: -3 | G4: 40.05 | H4: Payout Complete | I4: 46124 | J4: 11 | K4: 41.82 | L4: =+K4-E4 -> -1.23
A5: 2011 | B5: 2025 Topps Archives Aqua Scope Foilboard Roki Sasaki ROOKIE /75 #200 CGC AUTH | C5: 16 | D5: 1.05 | E5: 16.8 | F5: -3 | G5: 13.8 | H5: Payout Complete | I5: 46124 | J5: 10 | K5: 16.2 | L5: =+K5-E5 -> -0.6
A6: 1737 | B6: 2024 Topps Heritage Chrome Hot Box Refractor Ronald Acuna Jr. ERROR #321 CGC AUTH | C6: 15 | D6: 1.05 | E6: 15.75 | F6: -3 | G6: 12.75 | H6: Payout Complete | I6: 46124 | J6: 12 | K6: 15 | L6: =+K6-E6 -> -0.75
A7: 4488 | B7: 2024 Immaculate Collection Pink Chet Holmgren 15/15 #20 CGC AUTH | C7: 15 | D7: 1.05 | E7: 15.75 | F7: -3 | G7: 12.75 | H7: Payout Complete | I7: 46124 | J7: 7 | K7: 15 | L7: =+K7-E7 -> -0.75
A8: 1852 | B8: 2025 Bowman Chrome Yellow Refractor Mike Trout /75 #27 CGC AUTH | C8: 12 | D8: 1.05 | E8: 12.6 | F8: -3 | G8: 9.6 | H8: Payout Complete | I8: 46124 | J8: 6 | K8: 11.4 | L8: =+K8-E8 -> -1.2
A9: 1952 | B9: 2025 Panini The National VIP Tiger Stripes Paul Skenes #42 CGC AUTH | C9: 11 | D9: 1.05 | E9: 11.55 | F9: -3 | G9: 8.55 | H9: Payout Complete | I9: 46124 | J9: 4 | K9: 10.2 | L9: =+K9-E9 -> -1.35
A10: 4813 | B10: 2025 Topps Chrome Gold Wave Refractor Chet Holmgren /50 #134 CGC AUTH | C10: 10 | D10: 1.05 | E10: 10.5 | F10: -3 | G10: 7.5 | H10: Payout Complete | I10: 46124 | J10: 5 | K10: 9 | L10: =+K10-E10 -> -1.5
A11: 1159 | B11: 2019 Topps Chrome Vladimir Guerrero Jr. ROOKIE #201 CGC AUTH | C11: 6 | D11: 1.05 | E11: 6.3 | F11: -3 | G11: 3.3 | H11: Payout Complete | I11: 46124 | J11: 2 | K11: 4.2 | L11: =+K11-E11 -> -2.1
A12: 2000 | B12: 2025 Topps All Team Shohei Ohtani #ATT-3 CGC AUTH | C12: 5 | D12: 1.05 | E12: 5.25 | F12: -3 | G12: 2.25 | H12: Payout Complete | I12: 46124 | J12: 1 | K12: 3 | L12: =+K12-E12 -> -2.25
A14: =COUNTA(A2:A12) -> 11 | B14: TOTALS | C14: =SUM(C2:C12) -> 496 | E14: =+SUM(E2:E13) -> 536.8 | F14: =SUM(F2:F12) -> -33 | G14: =+SUM(G2:G12) -> 503.8 | H14: =COUNTA(H2:H12) -> 11 | L14: =SUM(L2:L12) -> -9.88

Sheet 4-19
A1: Lot No. | B1: Title | C1: Hammer Price | D1: Split | E1: JZ Gross Proceeds | F1: CGC Auth. Fee | G1: JZ Net Proceeds | H1: Payout Status | I1: Sale Date | J1: Bids | L1: WH Net
A2: 1405 | B2: 2024 Leaf Collective Press Pass Light Blue Shimmer Vladimir Guerrero AUTO 10/10 CGC AUTH | C2: 18 | D2: 1.05 | E2: 18.9 | F2: -3 | G2: 15.9 | H2: Payout Complete | I2: 46131 | J2: 9 | K2: 18.36 | L2: =+K2-E2 -> -0.54
A3: 961 | B3: 2019 Panini Chronicles Contenders Season Ticket Red Vladimir Guerrero Jr. RC AUTO /50 CGC AUTH | C3: 64 | D3: 1.05 | E3: 67.2 | F3: -3 | G3: 64.2 | H3: Payout Complete | I3: 46131 | J3: 19 | K3: 69.12 | L3: =+K3-E3 -> 1.92
A5: =COUNTA(A2:A3) -> 2 | B5: TOTALS | C5: =SUM(C2:C3) -> 82 | E5: =+SUM(E2:E4) -> 86.1 | F5: =SUM(F2:F3) -> -6 | G5: =+SUM(G2:G3) -> 80.1 | H5: =COUNTA(H2:H3) -> 2 | L5: =SUM(L2:L3) -> 1.38

Sheet 4-26
A1: Lot No. | B1: Title | C1: Hammer Price | D1: Split | E1: JZ Gross Proceeds | F1: CGC Auth. Fee | G1: JZ Net Proceeds | H1: Payout Status | I1: Sale Date | J1: Bids | L1: WH Net
A2: 4156 | B2: 2024 Immaculate Collection Premium Jared McCain ROOKIE PATCH AUTO /50 #PPA-JMC CGC AUTH | C2: 155 | D2: 1.075 | E2: 166.625 | F2: -3 | G2: 163.625 | H2: Payout Complete | I2: 46138 | J2: 21 | K2: 170.5 | L2: =+K2-E2 -> 3.875
A3: 4211 | B3: 2024 Panini One And One FOTL Ajay Mitchell ROOKIE PATCH AUTO 1/15 #RJJ-AJY CGC AUTH | C3: 130 | D3: 1.075 | E3: 139.75 | F3: -3 | G3: 136.75 | H3: Payout Complete | I3: 46138 | J3: 35 | K3: 143 | L3: =+K3-E3 -> 3.25
A4: 4578 | B4: 2025 Topps Chrome Gold Geometric Refractor Jayson Tatum /50 #49 CGC AUTH | C4: 96 | D4: 1.075 | E4: 103.2 | F4: -3 | G4: 100.2 | H4: Payout Complete | I4: 46138 | J4: 34 | K4: 103.68 | L4: =+K4-E4 -> 0.48
A5: 4157 | B5: 2024 Immaculate Collection Jared McCain ROOKIE PATCH AUTO /99 #122 CGC AUTH | C5: 58 | D5: 1.075 | E5: 62.35 | F5: -3 | G5: 59.35 | H5: Payout Complete | I5: 46138 | J5: 15 | K5: 62.64 | L5: =+K5-E5 -> 0.29
A6: 4148 | B6: 2024 Panini Flawless Dereck Lively II PATCH AUTO /25 #FPA-DLM CGC AUTH | C6: 37 | D6: 1.05 | E6: 38.85 | F6: -3 | G6: 35.85 | H6: Payout Complete | I6: 46138 | J6: 12 | K6: 37.74 | L6: =+K6-E6 -> -1.11
A7: 3875 | B7: 2023 Panini Premium Stock City Edition Silver Victor Wembanyama ROOKIE #25 CGC AUTH | C7: 36 | D7: 1.05 | E7: 37.8 | F7: -3 | G7: 34.8 | H7: Payout Complete | I7: 46138 | J7: 11 | K7: 36.72 | L7: =+K7-E7 -> -1.08
A8: 3905 | B8: 2023 Finest Masters Gold Geometric Refractor Donovan Mitchell AUTO /50 #MA-DM CGC AUTH | C8: 35 | D8: 1.05 | E8: 36.75 | F8: -3 | G8: 33.75 | H8: Payout Complete | I8: 46138 | J8: 9 | K8: 35.7 | L8: =+K8-E8 -> -1.05
A9: 4215 | B9: 2024 Panini Origins Elevation Red Jared McCain ROOKIE AUTO /49 #ES-JAR CGC AUTH | C9: 33 | D9: 1.05 | E9: 34.65 | F9: -3 | G9: 31.65 | H9: Payout Complete | I9: 46138 | J9: 8 | K9: 33.66 | L9: =+K9-E9 -> -0.99
A10: 4160 | B10: 2024 Immaculate Collection Sophisticated Signatures Karl-Anthony Towns AUTO /49 CGC AUTH | C10: 29 | D10: 1.05 | E10: 30.45 | F10: -3 | G10: 27.45 | H10: Payout Complete | I10: 46138 | J10: 12 | K10: 29.58 | L10: =+K10-E10 -> -0.87
A11: 3423 | B11: 2019 Panini Flawless Collegiate Gold Tyler Herro ROOKIE PATCH 10/10 #24 CGC AUTH | C11: 28 | D11: 1.05 | E11: 29.4 | F11: -3 | G11: 26.4 | H11: Payout Complete | I11: 46138 | J11: 12 | K11: 28.56 | L11: =+K11-E11 -> -0.84
A12: 4131 | B12: 2024 Donruss Optic Black Pandora Rob Dillingham ROOKIE /15 #259 CGC AUTH | C12: 24 | D12: 1.05 | E12: 25.2 | F12: -3 | G12: 22.2 | H12: Payout Complete | I12: 46138 | J12: 3 | K12: 24.48 | L12: =+K12-E12 -> -0.72
A13: 3427 | B13: 2019 Panini Origins Tyler Herro ROOKIE PATCH AUTO #177 CGC AUTH | D13: 1.05 | E13: 0 | F13: -3 | G13: 0 | H13: Cancelled - Unpaid | I13: 46138 | J13: 11 | K13: 24.48 | L13: 0
A14: 4155 | B14: 2024 Immaculate Collection Materials LaMelo Ball PATCH /99 #MAT-LMB CGC AUTH | C14: 21 | D14: 1.05 | E14: 22.05 | F14: -3 | G14: 19.05 | H14: Payout Complete | I14: 46138 | J14: 4 | K14: 21.42 | L14: =+K14-E14 -> -0.63
A15: 4153 | B15: 2024 Hoops Premium Green Scope Nikola Jokic /25 #12 CGC AUTH | C15: 19 | D15: 1.05 | E15: 19.95 | F15: -3 | G15: 16.95 | H15: Payout Complete | I15: 46138 | J15: 13 | K15: 19.38 | L15: =+K15-E15 -> -0.57
A16: 3653 | B16: 2022 Panini Prizm Silver Alperen Sengun AUTO #SIG-ALP CGC AUTH | C16: 18 | D16: 1.05 | E16: 18.9 | F16: -3 | G16: 15.9 | H16: Payout Complete | I16: 46138 | J16: 8 | K16: 18.36 | L16: =+K16-E16 -> -0.54
A17: 4605 | B17: 2025 Topps Chrome Raywave Refractor Victor Wembanyama #221 CGC AUTH | C17: 14 | D17: 1.05 | E17: 14.7 | F17: -3 | G17: 11.7 | H17: Payout Complete | I17: 46138 | J17: 8 | K17: 13.8 | L17: =+K17-E17 -> -0.9
A18: 4248 | B18: 2024 Panini Prizm Black Silver Evan Mobley AUTO #121 CGC AUTH | C18: 11 | D18: 1.05 | E18: 11.55 | F18: -3 | G18: 8.55 | H18: Payout Complete | I18: 46138 | J18: 7 | K18: 10.2 | L18: =+K18-E18 -> -1.35
A19: 4127 | B19: 2024 Donruss Optic Choice Blue Cade Cunningham /24 #26 CGC AUTH | C19: 10 | D19: 1.05 | E19: 10.5 | F19: -3 | G19: 7.5 | H19: Payout Complete | I19: 46138 | J19: 6 | K19: 9 | L19: =+K19-E19 -> -1.5
A20: 4606 | B20: 2025 Topps Chrome Red White & Blue Refractor Victor Wembanyama #221 CGC AUTH | C20: 10 | D20: 1.05 | E20: 10.5 | F20: -3 | G20: 7.5 | H20: Payout Complete | I20: 46138 | J20: 4 | K20: 9 | L20: =+K20-E20 -> -1.5
A21: 4220 | B21: 2024 Panini Photogenic In Motion Groovy Jared McCain ROOKIE /35 #2 CGC AUTH | C21: 9 | D21: 1.05 | E21: 9.45 | F21: -3 | G21: 6.45 | H21: Payout Complete | I21: 46138 | J21: 3 | K21: 7.8 | L21: =+K21-E21 -> -1.65
A22: 4161 | B22: 2024 Immaculate Collection Standout Memorabilia Jalen Williams PATCH /99 #SM-JLN CGC AUTH | C22: 8 | D22: 1.05 | E22: 8.4 | F22: -3 | G22: 5.4 | H22: Payout Complete | I22: 46138 | J22: 3 | K22: 6.6 | L22: =+K22-E22 -> -1.8
A23: 4577 | B23: 2025 Topps Chrome Refractor Nikola Jokic #25 CGC AUTH | C23: 5 | D23: 1.05 | E23: 5.25 | F23: -3 | G23: 2.25 | H23: Payout Complete | I23: 46138 | J23: 1 | K23: 3 | L23: =+K23-E23 -> -2.25
A25: =COUNTA(A2:A23) -> 22 | B25: TOTALS | C25: =SUM(C2:C23) -> 786 | E25: =+SUM(E2:E24) -> 836.275 | F25: =SUM(F2:F23) -> -66 | G25: =+SUM(G2:G23) -> 773.275 | H25: =COUNTA(H2:H23)-1 -> 21 | L25: =SUM(L2:L23) -> -11.455

Sheet 5-3
A1: Lot No. | B1: Title | C1: Hammer Price | D1: Split | E1: JZ Gross Proceeds | F1: CGC Auth. Fee | G1: JZ Net Proceeds | H1: Payout Status | I1: Sale Date | J1: Bids | L1: WH Net
A2: 4721 | B2: 2025 Topps Chrome Gold Geometric Refractor Victor Wembanyama /50 #221 CGC AUTH | C2: 675 | D2: 1.1 | E2: 742.5 | F2: -3 | G2: 739.5 | H2: Payout Complete | I2: 46145 | J2: 14 | K2: 749.25 | L2: =+K2-E2 -> 6.75
A3: 3623 | B3: 2019 Panini Flawless Collegiate Star Swatch Gold Donovan Mitchell PATCH AUTO /10 #17 CGC AUTH | C3: 155 | D3: 1.075 | E3: 166.625 | F3: -3 | G3: 163.625 | H3: Payout Complete | I3: 46145 | J3: 20 | K3: 170.5 | L3: =+K3-E3 -> 3.875
A4: 4357 | B4: 2024 Immaculate Collection Sneaker Swatches Gold Jared McCain ROOKIE PATCH AUTO /10 CGC AUTH | C4: 115 | D4: 1.075 | E4: 123.64 | F4: -3 | G4: 120.64 | H4: Payout Complete | I4: 46145 | J4: 8 | K4: 126.5 | L4: =+K4-E4 -> 2.86
A5: 4356 | B5: 2024 Immaculate Collection Gold Jared McCain ROOKIE PATCH AUTO /10 #122 CGC AUTH | C5: 115 | D5: 1.075 | E5: 123.63 | F5: -3 | G5: 120.63 | H5: Payout Complete | I5: 46145 | J5: 14 | K5: 126.5 | L5: =+K5-E5 -> 2.87
A6: 4358 | B6: 2024 Immaculate Collection Sneaker Red Jared McCain ROOKIE PATCH AUTO /25 #SSS-JMC CGC AUTH | C6: 94 | D6: 1.075 | E6: 101.05 | F6: -3 | G6: 98.05 | H6: Payout Complete | I6: 46145 | J6: 15 | K6: 101.52 | L6: =+K6-E6 -> 0.47
A7: 5344 | B7: 2023 Super Glow Marvin Harrison Jr. AUTO #MHJ-1 CGC AUTH | C7: 64 | D7: 1.075 | E7: 68.8 | F7: -3 | G7: 65.8 | H7: Payout Complete | I7: 46145 | J7: 21 | K7: 69.12 | L7: =+K7-E7 -> 0.32
A8: 4770 | B8: 2025 Topps Chrome Rock Stars Jayson Tatum #RS-1 CGC AUTH | C8: 44 | D8: 1.05 | E8: 46.2 | F8: -3 | G8: 43.2 | H8: Payout Complete | I8: 46145 | J8: 12 | K8: 44.88 | L8: =+K8-E8 -> -1.32
A9: 4783 | B9: 2025 Topps Chrome Tall Tales Orange Refractor Nikola Jokic /25 #TT-1 CGC AUTH | C9: 41 | D9: 1.05 | E9: 43.05 | F9: -3 | G9: 40.05 | H9: Payout Complete | I9: 46145 | J9: 8 | K9: 41.82 | L9: =+K9-E9 -> -1.23
A10: 4723 | B10: 2025 Topps Chrome Xfractor Victor Wembanyama #221 CGC AUTH | C10: 34 | D10: 1.05 | E10: 35.7 | F10: -3 | G10: 32.7 | H10: Payout Complete | I10: 46145 | J10: 13 | K10: 34.68 | L10: =+K10-E10 -> -1.02
A11: 3840 | B11: 2023 Bowman University Now Caitlin Clark ROOKIE #49 PSA 10 GEM MINT | C11: 33 | D11: 1.05 | E11: 34.65 | F11: -3 | G11: 31.65 | H11: Payout Complete | I11: 46145 | J11: 14 | K11: 33.66 | L11: =+K11-E11 -> -0.99
A12: 4337 | B12: 2024 Donruss Optic Jared McCain ROOKIE AUTO #313 CGC AUTH | C12: 21 | D12: 1.05 | E12: 22.05 | F12: -3 | G12: 19.05 | H12: Payout Complete | I12: 46145 | J12: 5 | K12: 21.42 | L12: =+K12-E12 -> -0.63
A13: 4722 | B13: 2025 Topps Chrome Refractor Victor Wembanyama #221 CGC AUTH | C13: 17 | D13: 1.05 | E13: 17.85 | F13: -3 | G13: 14.85 | H13: Payout Complete | I13: 46145 | J13: 7 | K13: 17.34 | L13: =+K13-E13 -> -0.51
... A18: 4760 | B18: 2025 Topps Chrome Inspirational Raywave Refractor Victor Wembanyama #IP-6 CGC AUTH | C18: 5 | D18: 1.05 | E18: 5.25 | F18: -3 | G18: 2.25 | H18: Payout Complete | I18: 46145 | J18: 1 | K18: 3 | L18: =+K18-E18 -> -2.25
A20: =COUNTA(A2:A18) -> 17 | B20: TOTALS | C20: =SUM(C2:C18) -> 1461 | E20: =+SUM(E2:E19) -> 1581.395 | F20: =SUM(F2:F18) -> -51 | G20: =+SUM(G2:G18) -> 1530.395 | H20: =COUNTA(H2:H18) -> 17 | L20: =SUM(L2:L18) -> 4.335

Sheet 5-10
A1: Lot No. | B1: Title | C1: Hammer Price | D1: Split | E1: JZ Gross Proceeds | F1: CGC Auth. Fee | G1: JZ Net Proceeds | H1: Payout Status | I1: Sale Date | J1: Bids | L1: WH Net
A2: 3903 | B2: 2022 Panini Flawless All-NBA Ink Blue Nikola Jokic AUTO /8 #ALL-NKJ | C2: 675 | D2: 1.1 | E2: =+C2*D2 -> 742.5 | F2: 0 | G2: =+E2+F2 -> 742.5 | H2: Payout Complete | I2: 46152 | J2: 11 | K2: 749.25 | L2: =+K2-E2 -> 6.75
A3: 3904 | B3: 2022 Panini One And One Nikola Jokic PATCH AUTO 25/25 #JA-NJK | C3: 430 | D3: 1.1 | E3: =+C3*D3 -> 473 | F3: 0 | G3: =+E3+F3 -> 473 | H3: Payout Complete | I3: 46152 | J3: 12 | K3: 477.3 | L3: =+K3-E3 -> 4.3
A4: 4486 | B4: 2024 Topps Chrome '73 Red Geometric Refractor Tyrese Haliburton AUTO 5/5 #73TA-TH CGC AUTH | C4: 260 | D4: 1.1 | E4: =+C4*D4 -> 286 | F4: -3 | G4: =+E4+F4 -> 283 | H4: Payout Complete | I4: 46152 | J4: 29 | K4: 288.6 | L4: =+K4-E4 -> 2.6
A5: 4353 | B5: 2024 Immaculate Collection Retro Premium Gold Jared McCain ROOKIE PATCH AUTO /10 CGC AUTH | C5: 230 | D5: 1.1 | E5: =+C5*D5 -> 253 | F5: -3 | G5: =+E5+F5 -> 250 | H5: Payout Complete | I5: 46152 | J5: 17 | K5: 255.3 | L5: =+K5-E5 -> 2.3
A6: 4354 | B6: 2024 Immaculate Collection Sneaker Jared McCain ROOKIE RELIC AUTO /49 #SSS-JMC CGC AUTH | C6: 140 | D6: 1.075 | E6: =+C6*D6 -> 150.5 | F6: -3 | G6: =+E6+F6 -> 147.5 | H6: Payout Complete | I6: 46152 | J6: 19 | K6: 154 | L6: =+K6-E6 -> 3.5
A7: 4485 | B7: 2024 Panini Silhouette King's Court Klay Thompson Stephen Curry Kevin Durant /99 #13 CGC AUTH | C7: 56 | D7: 1.075 | E7: =+C7*D7 -> 60.2 | F7: -3 | G7: =+E7+F7 -> 57.2 | H7: Payout Complete | I7: 46152 | J7: 20 | K7: 60.48 | L7: =+K7-E7 -> 0.28
A8: 4079 | B8: 2023 Panini Phoenix Thrillers Green Tyrese Haliburton 1/5 #21 CGC AUTH | C8: 38 | D8: 1.05 | E8: =+C8*D8 -> 39.9 | F8: -3 | G8: =+E8+F8 -> 36.9 | H8: Payout Complete | I8: 46152 | J8: 13 | K8: 38.76 | L8: =+K8-E8 -> -1.14
A9: 3936 | B9: 2022 Bowman Chrome University Invicta Caitlin Clark ROOKIE #BI-15 CGC AUTH | C9: 5 | D9: 1.05 | E9: =+C9*D9 -> 5.25 | F9: -3 | G9: =+E9+F9 -> 2.25 | H9: Payout Complete | I9: 46152 | J9: 1 | K9: 3 | L9: =+K9-E9 -> -2.25
A11: =COUNTA(A2:A9) -> 8 | B11: TOTALS | C11: =SUM(C2:C9) -> 1834 | E11: =+SUM(E2:E10) -> 2010.35 | F11: =SUM(F2:F9) -> -18 | G11: =+SUM(G2:G9) -> 1992.35 | H11: =COUNTA(H2:H9) -> 8 | L11: =SUM(L2:L9) -> 16.34
